Workbook

Sheet Scenarios probability
G2: Final ROC Ranking | I2: Probs
G3: P(S1∣S1,S2,S3) | H3: 3 | I3: 0.11111111
G4: P(S2∣S1,S2,S3) | H4: 1 | I4: 0.61111111
G5: P(S3∣S1,S2,S3) | H5: 2 | I5: 0.27777778

Sheet Elicitation of functions
A1: Attribute | B1: Scale type | C1: Worst plausible consequence | D1: Best plausible consequence | E1: Scale description
A2: Achievement of learning outcomes | B2: Natural percentage | C2: 0.65 | D2: 0.95 | E2: % of students meeting competency targets
A3: Completion and progression | B3: Natural percentage | C3: 0.55 | D3: 0.9 | E3: % of students completing within target time or target+1 year
A4: Learner experience and engagement | B4: Anchored categorical | C4: Very poor | D4: Excellent | E4: 1=Very poor; 2=Poor; 3=Acceptable; 4=Good; 5=Excellent
A5: Accessibility flexibility and equity | B5: Count / extent | C5: 0 | D5: 4 | E5: Number of learner profiles well supported: 0=None; 1=One; 2=Two; 3=Three; 4=All four
A6: Integrity of assessment | B6: Anchored categorical | C6: Fragile | D6: Exemplary | E6: 1=Fragile; 2=Basic; 3=Robust; 4=Exemplary
A7: Strategic control / autonomy | B7: Natural percentage | C7: 0.2 | D7: 0.9 | E7: % of critical learning/assessment/data infrastructure under Aalto or trusted regional control | F7: Achievement of learning outcomes
A8: External relevance and employability | B8: Natural percentage | C8: 0.65 | D8: 0.95 | E8: percentage of graduates in relevant employment or further study within 12 months | F8: t- | G8: t+ | H8: t | I8: U(x) | K8: U(x) | L8: t
A9: Global attractiveness / reputation | B9: Anchored categorical | C9: Local | D9: Globally distinctive | E9: 1=Local; 2=National; 3=Nordic-Baltic; 4=European; 5=Globally distinctive | F9: 0.65 | G9: 0.95 | H9: 0.8 | I9: 0.5 | K9: 0.65 | L9: 0
F10: =F9 -> 0.65 | G10: =H9 -> 0.8 | H10: 0.72 | I10: 0.25 | K10: 0.72 | L10: 0.25
F11: =H9 -> 0.8 | G11: =G9 -> 0.95 | H11: 0.85 | I11: 0.75 | K11: 0.8 | L11: 0.5
G12: x_0 | H12: 0.65 | I12: 0 | K12: 0.85 | L12: 0.75
G13: x_1 | H13: 0.95 | I13: 1 | K13: 0.95 | L13: 1
H14: 0.82 | I14: =IF(H14<H10,(I10-I12)/(H10-H12)*(H14-H12)+I12,IF(H14<H9,(I9-I10)/(H9-H10)*(H14-H10)+I10,IF(H14<H11,(I11-I9)/(H11-H9)*(H14-H9)+I9,(I13-I11)/(H13-H11)*(H14-H11)+I11))) -> 0.6
F17: Completion and progression | N17: t | O17: U(x)
F18: t- | G18: t+ | H18: t | I18: U(x) | N18: 0.55 | O18: 0
F19: 0.55 | G19: 0.9 | H19: 0.72 | I19: 0.5 | N19: 0.65 | O19: 0.25
F20: =F19 -> 0.55 | G20: =H19 -> 0.72 | H20: 0.65 | I20: 0.25 | N20: 0.72 | O20: 0.5
F21: =H19 -> 0.72 | G21: =G19 -> 0.9 | H21: 0.8 | I21: 0.75 | N21: 0.8 | O21: 0.75
G22: x_0 | H22: 0.55 | I22: 0 | N22: 0.9 | O22: 1
G23: x_1 | H23: 0.9 | I23: 1
H24: 0.55 | I24: =IF(H24<H20,(I20-I22)/(H20-H22)*(H24-H22)+I22,IF(H24<H19,(I19-I20)/(H19-H20)*(H24-H20)+I20,IF(H24<H21,(I21-I19)/(H21-H19)*(H24-H19)+I19,(I23-I21)/(H23-H21)*(H24-H21)+I21))) -> 0
F27: Learner experience and engagement | K27: U(x)
F28: t | G28: t- | H28: t+ | I28: p of t- | J28: p of t+
F29: Very poor | K29: 0
F30: Poor | G30: Very poor | H30: Excellent | I30: 0.8 | J30: 0.2 | K30: =I30 * $K$29 + J30 * $K$33 -> 0.2
F31: Acceptable | G31: Very poor | H31: Excellent | I31: 0.6 | J31: 0.4 | K31: =I31 * $K$29 + J31 * $K$33 -> 0.4
F32: Good | G32: Very poor | H32: Excellent | I32: 0.3 | J32: 0.7 | K32: =I32 * $K$29 + J32 * $K$33 -> 0.7
F33: Excellent | K33: 1
F37: Accessibility flexibility and equity | K37: U(x)
F38: t | G38: t- | H38: t+ | I38: p of t- | J38: p of t+
F39: 0 | K39: 0
F40: 1 | G40: 0 | H40: 4 | I40: 0.7 | J40: 0.3 | K40: =I40 * $K$29 + J40 * $K$33 -> 0.3
F41: 2 | G41: 0 | H41: 4 | I41: 0.5 | J41: 0.5 | K41: =I41 * $K$29 + J41 * $K$33 -> 0.5
F42: 3 | G42: 0 | H42: 4 | I42: 0.2 | J42: 0.8 | K42: =I42 * $K$29 + J42 * $K$33 -> 0.8
F43: 4 | K43: 1
F47: Integrity of Assessment | K47: U(x)
F48: t | G48: t- | H48: t+ | I48: p of t- | J48: p of t+
F49: Fragile | K49: 0
F50: Basic | G50: Fragile | H50: Exemplary | I50: 0.5 | J50: 0.5 | K50: =I50 * $K$29 + J50 * $K$33 -> 0.5
...

Sheet Elicitation of weights
A1: Attribute swung from worst to best | B1: Consequence to compare | C1: Rank | D1: Wj | E1: wj (ROC)
A2: (Benchmark) | B2: 65%,55%,1,0,1,20%,65%,1 | G2: =1/8 -> 0.125
A3: Achievement of learning outcomes | B3: 95%,55%,1,0,1,20%,65%,1 | C3: 5 | D3: =C3^(-1) -> 0.2 | E3: =(SUMIF($C$3:$C$10,">="&C3,$D$3:$D$10))*$G$2 -> 0.079315476
A4: Completion and progression | B4: 65%,90%,1,0,1,20%,65%,1 | C4: 2 | D4: =C4^(-1) -> 0.5 | E4: =(SUMIF($C$3:$C$10,">="&C4,$D$3:$D$10))*$G$2 -> 0.21473214
A5: Learner experience and engagement | B5: 65%,55%,5,0,1,20%,65%,1 | C5: 4 | D5: =C5^(-1) -> 0.25 | E5: =(SUMIF($C$3:$C$10,">="&C5,$D$3:$D$10))*$G$2 -> 0.11056548
A6: Accessibility flexibility and equity | B6: 65%,55%,1,4,1,20%,65%,1 | C6: 7 | D6: =C6^(-1) -> 0.14285714 | E6: =(SUMIF($C$3:$C$10,">="&C6,$D$3:$D$10))*$G$2 -> 0.033482143
A7: Integrity of assessment | B7: 65%,55%,1,0,4,20%,65%,1 | C7: 8 | D7: =C7^(-1) -> 0.125 | E7: =(SUMIF($C$3:$C$10,">="&C7,$D$3:$D$10))*$G$2 -> 0.015625
A8: Strategic control / autonomy | B8: 65%,55%,1,0,1,90%,65%,1 | C8: 6 | D8: =C8^(-1) -> 0.16666667 | E8: =(SUMIF($C$3:$C$10,">="&C8,$D$3:$D$10))*$G$2 -> 0.054315476
A9: External relevance and employability | B9: 65%,55%,1,0,1,20%,95%,1 | C9: 1 | D9: =C9^(-1) -> 1 | E9: =(SUMIF($C$3:$C$10,">="&C9,$D$3:$D$10))*$G$2 -> 0.33973214
A10: Global attractiveness / reputation | B10: 65%,55%,1,0,1,20%,65%,5 | C10: 3 | D10: =C10^(-1) -> 0.33333333 | E10: =(SUMIF($C$3:$C$10,">="&C10,$D$3:$D$10))*$G$2 -> 0.15223214
C11: Total | D11: 0 | E11: =SUM(E3:E10) -> 1

Sheet Action Performance by Scenario
L2: Attribute-specific value scores (0-1) linked from elicited value functions
B4: Scenario 1: Competitive Global Campus​ | L4: Scenario 1: Competitive Global Campus - Attribute-specific value scores
B5: Action | C5: Achievement of learning outcomes (65-95%) | D5: Completion and progression (55-90%) | E5: Learner experience and engagement | F5: Accessibility, flexibility and equity (0-4) | G5: Integrity of assessment | H5: Strategic control / autonomy (20-90%) | I5: External relevance and employability (65-95%) | J5: Global attractiveness / reputation (1-5) | L5: Action | M5: Achievement of learning outcomes (65-95%) | N5: Completion and progression (55-90%) | O5: Learner experience and engagement | P5: Accessibility, flexibility and equity (0-4) | Q5: Integrity of assessment | R5: Strategic control / autonomy (20-90%) | S5: External relevance and employability (65-95%) | T5: Global attractiveness / reputation (1-5)
B6: AI-Enabled Student Guidance | C6: 0.82 | D6: 0.78 | E6: Good | F6: 3 | G6: Basic | H6: 0.4 | I6: 0.82 | J6: 3 | L6: =B6 -> AI-Enabled Student Guidance | M6: =IF(C6<'Elicitation of functions'!$H$10,('Elicitation of functions'!$I$10-'Elicitation of functions'!$I$12)/('Elicitation of functions'!$H$10-'Elicitation of functions'!$H$12)*(C6-'Elicitation of functions'!$H$12)+'Elicitation of functions'!$I$12,IF(C6<'Elicitation of functions'!$H$9,('Elicitation of functions'!$I$9-'Elicitation of functions'!$I$10)/('Elicitation of functions'!$H$9-'Elicitation of functions'!$H$10)*(C6-'Elicitation of functions'!$H$10)+'Elicitation of functions'!$I$10,IF(C6<'Elicitation of functions'!$H$11,('Elicitation of functions'!$I$11-'Elicitation of functions'!$I$9)/('Elicitation of functions'!$H$11-'Elicitation of functions'!$H$9)*(C6-'Elicitation of functions'!$H$9)+'Elicitation of functions'!$I$9,('Elicitation of functions'!$I$13-'Elicitation of functions'!$I$11)/('Elicitation of functions'!$H$13-'Elicitation of functions'!$H$11)*(C6-'Elicitation of functions'!$H$11)+'Elicitation of functions'!$I$11))) -> 0.6 | N6: =IF(D6<'Elicitation of functions'!$H$20,('Elicitation of functions'!$I$20-'Elicitation of functions'!$I$22)/('Elicitation of functions'!$H$20-'Elicitation of functions'!$H$22)*(D6-'Elicitation of functions'!$H$22)+'Elicitation of functions'!$I$22,IF(D6<'Elicitation of functions'!$H$19,('Elicitation of functions'!$I$19-'Elicitation of functions'!$I$20)/('Elicitation of functions'!$H$19-'Elicitation of functions'!$H$20)*(D6-'Elicitation of functions'!$H$20)+'Elicitation of functions'!$I$20,IF(D6<'Elicitation of functions'!$H$21,('Elicitation of functions'!$I$21-'Elicitation of functions'!$I$19)/('Elicitation of functions'!$H$21-'Elicitation of functions'!$H$19)*(D6-'Elicitation of functions'!$H$19)+'Elicitation of functions'!$I$19,('Elicitation of functions'!$I$23-'Elicitation of functions'!$I$21)/('Elicitation of functions'!$H$23-'Elicitation of functions'!$H$21)*(D6-'Elicitation of functions'!$H$21)+'Elicitation of functions'!$I$21))) -> 0.6875 | O6: =INDEX('Elicitation of functions'!$K$29:$K$33,MATCH(E6,'Elicitation of functions'!$F$29:$F$33,0)) -> 0.7 | P6: =INDEX('Elicitation of functions'!$K$39:$K$43,MATCH(F6,'Elicitation of functions'!$F$39:$F$43,0)) -> 0.8 | Q6: =INDEX('Elicitation of functions'!$K$49:$K$52,MATCH(G6,'Elicitation of functions'!$F$49:$F$52,0)) -> 0.5 | R6: =IF(H6<'Elicitation of functions'!$H$60,('Elicitation of functions'!$I$60-'Elicitation of functions'!$I$62)/('Elicitation of functions'!$H$60-'Elicitation of functions'!$H$62)*(H6-'Elicitation of functions'!$H$62)+'Elicitation of functions'!$I$62,IF(H6<'Elicitation of functions'!$H$59,('Elicitation of functions'!$I$59-'Elicitation of functions'!$I$60)/('Elicitation of functions'!$H$59-'Elicitation of functions'!$H$60)*(H6-'Elicitation of functions'!$H$60)+'Elicitation of functions'!$I$60,IF(H6<'Elicitation of functions'!$H$61,('Elicitation of functions'!$I$61-'Elicitation of functions'!$I$59)/('Elicitation of functions'!$H$61-'Elicitation of functions'!$H$59)*(H6-'Elicitation of functions'!$H$59)+'Elicitation of functions'!$I$59,('Elicitation of functions'!$I$63-'Elicitation of functions'!$I$61)/('Elicitation of functions'!$H$63-'Elicitation of functions'!$H$61)*(H6-'Elicitation of functions'!$H$61)+'Elicitation of functions'!$I$61))) -> 0.41666667 | S6: =IF(I6<'Elicitation of functions'!$H$70,('Elicitation of functions'!$I$70-'Elicitation of functions'!$I$72)/('Elicitation of functions'!$H$70-'Elicitation of functions'!$H$72)*(I6-'Elicitation of functions'!$H$72)+'Elicitation of functions'!$I$72,IF(I6<'Elicitation of functions'!$H$69,('Elicitation of functions'!$I$69-'Elicitation of functions'!$I$70)/('Elicitation of functions'!$H$69-'Elicitation of functions'!$H$70)*(I6-'Elicitation of functions'!$H$70)+'Elicitation of functions'!$I$70,IF(I6<'Elicitation of functions'!$H$71,('Elicitation of functions'!$I$71-'Elicitation of functions'!$I$69)/('Elicitation of functions'!$H$71-'Elicitation of functions'!$H$69)*(I6-'Elicitation of functions'!$H$69)+'Elicitation of functions'!$I$69,('Elicitation of functions'!$I$73-'Elicitation of functions'!$I$71)/('Elicitation of functions'!$H$73-'Elicitation of functions'!$H$71)*(I6-'Elicitation of functions'!$H$71)+'Elicitation of functions'!$I$71))) -> 0.5 | T6: =INDEX('Elicitation of functions'!$K$79:$K$83,MATCH(J6,'Elicitation of functions'!$F$79:$F$83,0)) -> 0.35 | V6: 0.8 | W6: 0.5 | X6: 0.416667 | Y6: 0.5 | Z6: 0.35
B7: Elite Mentor Network / Smart Work-Study | C7: 0.85 | D7: 0.75 | E7: Excellent | F7: 1 | G7: Robust | H7: 0.45 | I7: 0.9 | J7: 4 | L7: =B7 -> Elite Mentor Network / Smart Work-Study | M7: =IF(C7<'Elicitation of functions'!$H$10,('Elicitation of functions'!$I$10-'Elicitation of functions'!$I$12)/('Elicitation of functions'!$H$10-'Elicitation of functions'!$H$12)*(C7-'Elicitation of functions'!$H$12)+'Elicitation of functions'!$I$12,IF(C7<'Elicitation of functions'!$H$9,('Elicitation of functions'!$I$9-'Elicitation of functions'!$I$10)/('Elicitation of functions'!$H$9-'Elicitation of functions'!$H$10)*(C7-'Elicitation of functions'!$H$10)+'Elicitation of functions'!$I$10,IF(C7<'Elicitation of functions'!$H$11,('Elicitation of functions'!$I$11-'Elicitation of functions'!$I$9)/('Elicitation of functions'!$H$11-'Elicitation of functions'!$H$9)*(C7-'Elicitation of functions'!$H$9)+'Elicitation of functions'!$I$9,('Elicitation of functions'!$I$13-'Elicitation of functions'!$I$11)/('Elicitation of functions'!$H$13-'Elicitation of functions'!$H$11)*(C7-'Elicitation of functions'!$H$11)+'Elicitation of functions'!$I$11))) -> 0.75 | N7: =IF(D7<'Elicitation of functions'!$H$20,('Elicitation of functions'!$I$20-'Elicitation of functions'!$I$22)/('Elicitation of functions'!$H$20-'Elicitation of functions'!$H$22)*(D7-'Elicitation of functions'!$H$22)+'Elicitation of functions'!$I$22,IF(D7<'Elicitation of functions'!$H$19,('Elicitation of functions'!$I$19-'Elicitation of functions'!$I$20)/('Elicitation of functions'!$H$19-'Elicitation of functions'!$H$20)*(D7-'Elicitation of functions'!$H$20)+'Elicitation of functions'!$I$20,IF(D7<'Elicitation of functions'!$H$21,('Elicitation of functions'!$I$21-'Elicitation of functions'!$I$19)/('Elicitation of functions'!$H$21-'Elicitation of functions'!$H$19)*(D7-'Elicitation of functions'!$H$19)+'Elicitation of functions'!$I$19,('Elicitation of functions'!$I$23-'Elicitation of functions'!$I$21)/('Elicitation of functions'!$H$23-'Elicitation of functions'!$H$21)*(D7-'Elicitation of functions'!$H$21)+'Elicitation of functions'!$I$21))) -> 0.59375 | O7: =INDEX('Elicitation of functions'!$K$29:$K$33,MATCH(E7,'Elicitation of functions'!$F$29:$F$33,0)) -> 1 | P7: =INDEX('Elicitation of functions'!$K$39:$K$43,MATCH(F7,'Elicitation of functions'!$F$39:$F$43,0)) -> 0.3 | Q7: =INDEX('Elicitation of functions'!$K$49:$K$52,MATCH(G7,'Elicitation of functions'!$F$49:$F$52,0)) -> 0.75 | R7: =IF(H7<'Elicitation of functions'!$H$60,('Elicitation of functions'!$I$60-'Elicitation of functions'!$I$62)/('Elicitation of functions'!$H$60-'Elicitation of functions'!$H$62)*(H7-'Elicitation of functions'!$H$62)+'Elicitation of functions'!$I$62,IF(H7<'Elicitation of functions'!$H$59,('Elicitation of functions'!$I$59-'Elicitation of functions'!$I$60)/('Elicitation of functions'!$H$59-'Elicitation of functions'!$H$60)*(H7-'Elicitation of functions'!$H$60)+'Elicitation of functions'!$I$60,IF(H7<'Elicitation of functions'!$H$61,('Elicitation of functions'!$I$61-'Elicitation of functions'!$I$59)/('Elicitation of functions'!$H$61-'Elicitation of functions'!$H$59)*(H7-'Elicitation of functions'!$H$59)+'Elicitation of functions'!$I$59,('Elicitation of functions'!$I$63-'Elicitation of functions'!$I$61)/('Elicitation of functions'!$H$63-'Elicitation of functions'!$H$61)*(H7-'Elicitation of functions'!$H$61)+'Elicitation of functions'!$I$61))) -> 0.5 | S7: =IF(I7<'Elicitation of functions'!$H$70,('Elicitation of functions'!$I$70-'Elicitation of functions'!$I$72)/('Elicitation of functions'!$H$70-'Elicitation of functions'!$H$72)*(I7-'Elicitation of functions'!$H$72)+'Elicitation of functions'!$I$72,IF(I7<'Elicitation of functions'!$H$69,('Elicitation of functions'!$I$69-'Elicitation of functions'!$I$70)/('Elicitation of functions'!$H$69-'Elicitation of functions'!$H$70)*(I7-'Elicitation of functions'!$H$70)+'Elicitation of functions'!$I$70,IF(I7<'Elicitation of functions'!$H$71,('Elicitation of functions'!$I$71-'Elicitation of functions'!$I$69)/('Elicitation of functions'!$H$71-'Elicitation of functions'!$H$69)*(I7-'Elicitation of functions'!$H$69)+'Elicitation of functions'!$I$69,('Elicitation of functions'!$I$73-'Elicitation of functions'!$I$71)/('Elicitation of functions'!$H$73-'Elicitation of functions'!$H$71)*(I7-'Elicitation of functions'!$H$71)+'Elicitation of functions'!$I$71))) -> 0.75 | T7: =INDEX('Elicitation of functions'!$K$79:$K$83,MATCH(J7,'Elicitation of functions'!$F$79:$F$83,0)) -> 0.7 | V7: 0.3 | W7: 0.75 | X7: 0.5 | Y7: 0.75 | Z7: 0.7
B8: AI Governance Board / Assessment Integrity | C8: 0.75 | D8: 0.65 | E8: Poor | F8: 2 | G8: Exemplary | H8: 0.6 | I8: 0.8 | J8: 3 | L8: =B8 -> AI Governance Board / Assessment Integrity | M8: =IF(C8<'Elicitation of functions'!$H$10,('Elicitation of functions'!$I$10-'Elicitation of functions'!$I$12)/('Elicitation of functions'!$H$10-'Elicitation of functions'!$H$12)*(C8-'Elicitation of functions'!$H$12)+'Elicitation of functions'!$I$12,IF(C8<'Elicitation of functions'!$H$9,('Elicitation of functions'!$I$9-'Elicitation of functions'!$I$10)/('Elicitation of functions'!$H$9-'Elicitation of functions'!$H$10)*(C8-'Elicitation of functions'!$H$10)+'Elicitation of functions'!$I$10,IF(C8<'Elicitation of functions'!$H$11,('Elicitation of functions'!$I$11-'Elicitation of functions'!$I$9)/('Elicitation of functions'!$H$11-'Elicitation of functions'!$H$9)*(C8-'Elicitation of functions'!$H$9)+'Elicitation of functions'!$I$9,('Elicitation of functions'!$I$13-'Elicitation of functions'!$I$11)/('Elicitation of functions'!$H$13-'Elicitation of functions'!$H$11)*(C8-'Elicitation of functions'!$H$11)+'Elicitation of functions'!$I$11))) -> 0.34375 | N8: =IF(D8<'Elicitation of functions'!$H$20,('Elicitation of functions'!$I$20-'Elicitation of functions'!$I$22)/('Elicitation of functions'!$H$20-'Elicitation of functions'!$H$22)*(D8-'Elicitation of functions'!$H$22)+'Elicitation of functions'!$I$22,IF(D8<'Elicitation of functions'!$H$19,('Elicitation of functions'!$I$19-'Elicitation of functions'!$I$20)/('Elicitation of functions'!$H$19-'Elicitation of functions'!$H$20)*(D8-'Elicitation of functions'!$H$20)+'Elicitation of functions'!$I$20,IF(D8<'Elicitation of functions'!$H$21,('Elicitation of functions'!$I$21-'Elicitation of functions'!$I$19)/('Elicitation of functions'!$H$21-'Elicitation of functions'!$H$19)*(D8-'Elicitation of functions'!$H$19)+'Elicitation of functions'!$I$19,('Elicitation of functions'!$I$23-'Elicitation of functions'!$I$21)/('Elicitation of functions'!$H$23-'Elicitation of functions'!$H$21)*(D8-'Elicitation of functions'!$H$21)+'Elicitation of functions'!$I$21))) -> 0.25 | O8: =INDEX('Elicitation of functions'!$K$29:$K$33,MATCH(E8,'Elicitation of functions'!$F$29:$F$33,0)) -> 0.2 | P8: =INDEX('Elicitation of functions'!$K$39:$K$43,MATCH(F8,'Elicitation of functions'!$F$39:$F$43,0)) -> 0.5 | Q8: =INDEX('Elicitation of functions'!$K$49:$K$52,MATCH(G8,'Elicitation of functions'!$F$49:$F$52,0)) -> 1 | R8: =IF(H8<'Elicitation of functions'!$H$60,('Elicitation of functions'!$I$60-'Elicitation of functions'!$I$62)/('Elicitation of functions'!$H$60-'Elicitation of functions'!$H$62)*(H8-'Elicitation of functions'!$H$62)+'Elicitation of functions'!$I$62,IF(H8<'Elicitation of functions'!$H$59,('Elicitation of functions'!$I$59-'Elicitation of functions'!$I$60)/('Elicitation of functions'!$H$59-'Elicitation of functions'!$H$60)*(H8-'Elicitation of functions'!$H$60)+'Elicitation of functions'!$I$60,IF(H8<'Elicitation of functions'!$H$61,('Elicitation of functions'!$I$61-'Elicitation of functions'!$I$59)/('Elicitation of functions'!$H$61-'Elicitation of functions'!$H$59)*(H8-'Elicitation of functions'!$H$59)+'Elicitation of functions'!$I$59,('Elicitation of functions'!$I$63-'Elicitation of functions'!$I$61)/('Elicitation of functions'!$H$63-'Elicitation of functions'!$H$61)*(H8-'Elicitation of functions'!$H$61)+'Elicitation of functions'!$I$61))) -> 0.625 | S8: =IF(I8<'Elicitation of functions'!$H$70,('Elicitation of functions'!$I$70-'Elicitation of functions'!$I$72)/('Elicitation of functions'!$H$70-'Elicitation of functions'!$H$72)*(I8-'Elicitation of functions'!$H$72)+'Elicitation of functions'!$I$72,IF(I8<'Elicitation of functions'!$H$69,('Elicitation of functions'!$I$69-'Elicitation of functions'!$I$70)/('Elicitation of functions'!$H$69-'Elicitation of functions'!$H$70)*(I8-'Elicitation of functions'!$H$70)+'Elicitation of functions'!$I$70,IF(I8<'Elicitation of functions'!$H$71,('Elicitation of functions'!$I$71-'Elicitation of functions'!$I$69)/('Elicitation of functions'!$H$71-'Elicitation of functions'!$H$69)*(I8-'Elicitation of functions'!$H$69)+'Elicitation of functions'!$I$69,('Elicitation of functions'!$I$73-'Elicitation of functions'!$I$71)/('Elicitation of functions'!$H$73-'Elicitation of functions'!$H$71)*(I8-'Elicitation of functions'!$H$71)+'Elicitation of functions'!$I$71))) -> 0.45454545 | T8: =INDEX('Elicitation of functions'!$K$79:$K$83,MATCH(J8,'Elicitation of functions'!$F$79:$F$83,0)) -> 0.35 | V8: 0.5 | W8: 1 | X8: 0.625 | Y8: 0.454545 | Z8: 0.35
B9: Aalto-Controlled Core Infrastructure | C9: 0.8 | D9: 0.72 | E9: Acceptable | F9: 2 | G9: Robust | H9: 0.8 | I9: 0.82 | J9: 2 | L9: =B9 -> Aalto-Controlled Core Infrastructure | M9: =IF(C9<'Elicitation of functions'!$H$10,('Elicitation of functions'!$I$10-'Elicitation of functions'!$I$12)/('Elicitation of functions'!$H$10-'Elicitation of functions'!$H$12)*(C9-'Elicitation of functions'!$H$12)+'Elicitation of functions'!$I$12,IF(C9<'Elicitation of functions'!$H$9,('Elicitation of functions'!$I$9-'Elicitation of functions'!$I$10)/('Elicitation of functions'!$H$9-'Elicitation of functions'!$H$10)*(C9-'Elicitation of functions'!$H$10)+'Elicitation of functions'!$I$10,IF(C9<'Elicitation of functions'!$H$11,('Elicitation of functions'!$I$11-'Elicitation of functions'!$I$9)/('Elicitation of functions'!$H$11-'Elicitation of functions'!$H$9)*(C9-'Elicitation of functions'!$H$9)+'Elicitation of functions'!$I$9,('Elicitation of functions'!$I$13-'Elicitation of functions'!$I$11)/('Elicitation of functions'!$H$13-'Elicitation of functions'!$H$11)*(C9-'Elicitation of functions'!$H$11)+'Elicitation of functions'!$I$11))) -> 0.5 | N9: =IF(D9<'Elicitation of functions'!$H$20,('Elicitation of functions'!$I$20-'Elicitation of functions'!$I$22)/('Elicitation of functions'!$H$20-'Elicitation of functions'!$H$22)*(D9-'Elicitation of functions'!$H$22)+'Elicitation of functions'!$I$22,IF(D9<'Elicitation of functions'!$H$19,('Elicitation of functions'!$I$19-'Elicitation of functions'!$I$20)/('Elicitation of functions'!$H$19-'Elicitation of functions'!$H$20)*(D9-'Elicitation of functions'!$H$20)+'Elicitation of functions'!$I$20,IF(D9<'Elicitation of functions'!$H$21,('Elicitation of functions'!$I$21-'Elicitation of functions'!$I$19)/('Elicitation of functions'!$H$21-'Elicitation of functions'!$H$19)*(D9-'Elicitation of functions'!$H$19)+'Elicitation of functions'!$I$19,('Elicitation of functions'!$I$23-'Elicitation of functions'!$I$21)/('Elicitation of functions'!$H$23-'Elicitation of functions'!$H$21)*(D9-'Elicitation of functions'!$H$21)+'Elicitation of functions'!$I$21))) -> 0.5 | O9: =INDEX('Elicitation of functions'!$K$29:$K$33,MATCH(E9,'Elicitation of functions'!$F$29:$F$33,0)) -> 0.4 | P9: =INDEX('Elicitation of functions'!$K$39:$K$43,MATCH(F9,'Elicitation of functions'!$F$39:$F$43,0)) -> 0.5 | Q9: =INDEX('Elicitation of functions'!$K$49:$K$52,MATCH(G9,'Elicitation of functions'!$F$49:$F$52,0)) -> 0.75 | R9: =IF(H9<'Elicitation of functions'!$H$60,('Elicitation of functions'!$I$60-'Elicitation of functions'!$I$62)/('Elicitation of functions'!$H$60-'Elicitation of functions'!$H$62)*(H9-'Elicitation of functions'!$H$62)+'Elicitation of functions'!$I$62,IF(H9<'Elicitation of functions'!$H$59,('Elicitation of functions'!$I$59-'Elicitation of functions'!$I$60)/('Elicitation of functions'!$H$59-'Elicitation of functions'!$H$60)*(H9-'Elicitation of functions'!$H$60)+'Elicitation of functions'!$I$60,IF(H9<'Elicitation of functions'!$H$61,('Elicitation of functions'!$I$61-'Elicitation of functions'!$I$59)/('Elicitation of functions'!$H$61-'Elicitation of functions'!$H$59)*(H9-'Elicitation of functions'!$H$59)+'Elicitation of functions'!$I$59,('Elicitation of functions'!$I$63-'Elicitation of functions'!$I$61)/('Elicitation of functions'!$H$63-'Elicitation of functions'!$H$61)*(H9-'Elicitation of functions'!$H$61)+'Elicitation of functions'!$I$61))) -> 0.83333333 | S9: =IF(I9<'Elicitation of functions'!$H$70,('Elicitation of functions'!$I$70-'Elicitation of functions'!$I$72)/('Elicitation of functions'!$H$70-'Elicitation of functions'!$H$72)*(I9-'Elicitation of functions'!$H$72)+'Elicitation of functions'!$I$72,IF(I9<'Elicitation of functions'!$H$69,('Elicitation of functions'!$I$69-'Elicitation of functions'!$I$70)/('Elicitation of functions'!$H$69-'Elicitation of functions'!$H$70)*(I9-'Elicitation of functions'!$H$70)+'Elicitation of functions'!$I$70,IF(I9<'Elicitation of functions'!$H$71,('Elicitation of functions'!$I$71-'Elicitation of functions'!$I$69)/('Elicitation of functions'!$H$71-'Elicitation of functions'!$H$69)*(I9-'Elicitation of functions'!$H$69)+'Elicitation of functions'!$I$69,('Elicitation of functions'!$I$73-'Elicitation of functions'!$I$71)/('Elicitation of functions'!$H$73-'Elicitation of functions'!$H$71)*(I9-'Elicitation of functions'!$H$71)+'Elicitation of functions'!$I$71))) -> 0.5 | T9: =INDEX('Elicitation of functions'!$K$79:$K$83,MATCH(J9,'Elicitation of functions'!$F$79:$F$83,0)) -> 0.2 | V9: 0.5 | W9: 0.75 | X9: 0.833333 | Y9: 0.5 | Z9: 0.2
B10: Aalto-Certified Micro-Credentials | C10: 0.8 | D10: 0.75 | E10: Good | F10: 4 | G10: Basic | H10: 0.5 | I10: 0.88 | J10: 4 | L10: =B10 -> Aalto-Certified Micro-Credentials | M10: =IF(C10<'Elicitation of functions'!$H$10,('Elicitation of functions'!$I$10-'Elicitation of functions'!$I$12)/('Elicitation of functions'!$H$10-'Elicitation of functions'!$H$12)*(C10-'Elicitation of functions'!$H$12)+'Elicitation of functions'!$I$12,IF(C10<'Elicitation of functions'!$H$9,('Elicitation of functions'!$I$9-'Elicitation of functions'!$I$10)/('Elicitation of functions'!$H$9-'Elicitation of functions'!$H$10)*(C10-'Elicitation of functions'!$H$10)+'Elicitation of functions'!$I$10,IF(C10<'Elicitation of functions'!$H$11,('Elicitation of functions'!$I$11-'Elicitation of functions'!$I$9)/('Elicitation of functions'!$H$11-'Elicitation of functions'!$H$9)*(C10-'Elicitation of functions'!$H$9)+'Elicitation of functions'!$I$9,('Elicitation of functions'!$I$13-'Elicitation of functions'!$I$11)/('Elicitation of functions'!$H$13-'Elicitation of functions'!$H$11)*(C10-'Elicitation of functions'!$H$11)+'Elicitation of functions'!$I$11))) -> 0.5 | N10: =IF(D10<'Elicitation of functions'!$H$20,('Elicitation of functions'!$I$20-'Elicitation of functions'!$I$22)/('Elicitation of functions'!$H$20-'Elicitation of functions'!$H$22)*(D10-'Elicitation of functions'!$H$22)+'Elicitation of functions'!$I$22,IF(D10<'Elicitation of functions'!$H$19,('Elicitation of functions'!$I$19-'Elicitation of functions'!$I$20)/('Elicitation of functions'!$H$19-'Elicitation of functions'!$H$20)*(D10-'Elicitation of functions'!$H$20)+'Elicitation of functions'!$I$20,IF(D10<'Elicitation of functions'!$H$21,('Elicitation of functions'!$I$21-'Elicitation of functions'!$I$19)/('Elicitation of functions'!$H$21-'Elicitation of functions'!$H$19)*(D10-'Elicitation of functions'!$H$19)+'Elicitation of functions'!$I$19,('Elicitation of functions'!$I$23-'Elicitation of functions'!$I$21)/('Elicitation of functions'!$H$23-'Elicitation of functions'!$H$21)*(D10-'Elicitation of functions'!$H$21)+'Elicitation of functions'!$I$21))) -> 0.59375 | O10: =INDEX('Elicitation of functions'!$K$29:$K$33,MATCH(E10,'Elicitation of functions'!$F$29:$F$33,0)) -> 0.7 | P10: =INDEX('Elicitation of functions'!$K$39:$K$43,MATCH(F10,'Elicitation of functions'!$F$39:$F$43,0)) -> 1 | Q10: =INDEX('Elicitation of functions'!$K$49:$K$52,MATCH(G10,'Elicitation of functions'!$F$49:$F$52,0)) -> 0.5 | R10: =IF(H10<'Elicitation of functions'!$H$60,('Elicitation of functions'!$I$60-'Elicitation of functions'!$I$62)/('Elicitation of functions'!$H$60-'Elicitation of functions'!$H$62)*(H10-'Elicitation of functions'!$H$62)+'Elicitation of functions'!$I$62,IF(H10<'Elicitation of functions'!$H$59,('Elicitation of functions'!$I$59-'Elicitation of functions'!$I$60)/('Elicitation of functions'!$H$59-'Elicitation of functions'!$H$60)*(H10-'Elicitation of functions'!$H$60)+'Elicitation of functions'!$I$60,IF(H10<'Elicitation of functions'!$H$61,('Elicitation of functions'!$I$61-'Elicitation of functions'!$I$59)/('Elicitation of functions'!$H$61-'Elicitation of functions'!$H$59)*(H10-'Elicitation of functions'!$H$59)+'Elicitation of functions'!$I$59,('Elicitation of functions'!$I$63-'Elicitation of functions'!$I$61)/('Elicitation of functions'!$H$63-'Elicitation of functions'!$H$61)*(H10-'Elicitation of functions'!$H$61)+'Elicitation of functions'!$I$61))) -> 0.54166667 | S10: =IF(I10<'Elicitation of functions'!$H$70,('Elicitation of functions'!$I$70-'Elicitation of functions'!$I$72)/('Elicitation of functions'!$H$70-'Elicitation of functions'!$H$72)*(I10-'Elicitation of functions'!$H$72)+'Elicitation of functions'!$I$72,IF(I10<'Elicitation of functions'!$H$69,('Elicitation of functions'!$I$69-'Elicitation of functions'!$I$70)/('Elicitation of functions'!$H$69-'Elicitation of functions'!$H$70)*(I10-'Elicitation of functions'!$H$70)+'Elicitation of functions'!$I$70,IF(I10<'Elicitation of functions'!$H$71,('Elicitation of functions'!$I$71-'Elicitation of functions'!$I$69)/('Elicitation of functions'!$H$71-'Elicitation of functions'!$H$69)*(I10-'Elicitation of functions'!$H$69)+'Elicitation of functions'!$I$69,('Elicitation of functions'!$I$73-'Elicitation of functions'!$I$71)/('Elicitation of functions'!$H$73-'Elicitation of functions'!$H$71)*(I10-'Elicitation of functions'!$H$71)+'Elicitation of functions'!$I$71))) -> 0.6875 | T10: =INDEX('Elicitation of functions'!$K$79:$K$83,MATCH(J10,'Elicitation of functions'!$F$79:$F$83,0)) -> 0.7 | V10: 1 | W10: 0.5 | X10: 0.541667 | Y10: 0.6875 | Z10: 0.7
B11: Pedagogical Training for Staff | C11: 0.85 | D11: 0.78 | E11: Good | F11: 2 | G11: Robust | H11: 0.5 | I11: 0.84 | J11: 3 | L11: =B11 -> Pedagogical Training for Staff | M11: =IF(C11<'Elicitation of functions'!$H$10,('Elicitation of functions'!$I$10-'Elicitation of functions'!$I$12)/('Elicitation of functions'!$H$10-'Elicitation of functions'!$H$12)*(C11-'Elicitation of functions'!$H$12)+'Elicitation of functions'!$I$12,IF(C11<'Elicitation of functions'!$H$9,('Elicitation of functions'!$I$9-'Elicitation of functions'!$I$10)/('Elicitation of functions'!$H$9-'Elicitation of functions'!$H$10)*(C11-'Elicitation of functions'!$H$10)+'Elicitation of functions'!$I$10,IF(C11<'Elicitation of functions'!$H$11,('Elicitation of functions'!$I$11-'Elicitation of functions'!$I$9)/('Elicitation of functions'!$H$11-'Elicitation of functions'!$H$9)*(C11-'Elicitation of functions'!$H$9)+'Elicitation of functions'!$I$9,('Elicitation of functions'!$I$13-'Elicitation of functions'!$I$11)/('Elicitation of functions'!$H$13-'Elicitation of functions'!$H$11)*(C11-'Elicitation of functions'!$H$11)+'Elicitation of functions'!$I$11))) -> 0.75 | N11: =IF(D11<'Elicitation of functions'!$H$20,('Elicitation of functions'!$I$20-'Elicitation of functions'!$I$22)/('Elicitation of functions'!$H$20-'Elicitation of functions'!$H$22)*(D11-'Elicitation of functions'!$H$22)+'Elicitation of functions'!$I$22,IF(D11<'Elicitation of functions'!$H$19,('Elicitation of functions'!$I$19-'Elicitation of functions'!$I$20)/('Elicitation of functions'!$H$19-'Elicitation of functions'!$H$20)*(D11-'Elicitation of functions'!$H$20)+'Elicitation of functions'!$I$20,IF(D11<'Elicitation of functions'!$H$21,('Elicitation of functions'!$I$21-'Elicitation of functions'!$I$19)/('Elicitation of functions'!$H$21-'Elicitation of functions'!$H$19)*(D11-'Elicitation of functions'!$H$19)+'Elicitation of functions'!$I$19,('Elicitation of functions'!$I$23-'Elicitation of functions'!$I$21)/('Elicitation of functions'!$H$23-'Elicitation of functions'!$H$21)*(D11-'Elicitation of functions'!$H$21)+'Elicitation of functions'!$I$21))) -> 0.6875 | O11: =INDEX('Elicitation of functions'!$K$29:$K$33,MATCH(E11,'Elicitation of functions'!$F$29:$F$33,0)) -> 0.7 | P11: =INDEX('Elicitation of functions'!$K$39:$K$43,MATCH(F11,'Elicitation of functions'!$F$39:$F$43,0)) -> 0.5 | Q11: =INDEX('Elicitation of functions'!$K$49:$K$52,MATCH(G11,'Elicitation of functions'!$F$49:$F$52,0)) -> 0.75 | R11: =IF(H11<'Elicitation of functions'!$H$60,('Elicitation of functions'!$I$60-'Elicitation of functions'!$I$62)/('Elicitation of functions'!$H$60-'Elicitation of functions'!$H$62)*(H11-'Elicitation of functions'!$H$62)+'Elicitation of functions'!$I$62,IF(H11<'Elicitation of functions'!$H$59,('Elicitation of functions'!$I$59-'Elicitation of functions'!$I$60)/('Elicitation of functions'!$H$59-'Elicitation of functions'!$H$60)*(H11-'Elicitation of functions'!$H$60)+'Elicitation of functions'!$I$60,IF(H11<'Elicitation of functions'!$H$61,('Elicitation of functions'!$I$61-'Elicitation of functions'!$I$59)/('Elicitation of functions'!$H$61-'Elicitation of functions'!$H$59)*(H11-'Elicitation of functions'!$H$59)+'Elicitation of functions'!$I$59,('Elicitation of functions'!$I$63-'Elicitation of functions'!$I$61)/('Elicitation of functions'!$H$63-'Elicitation of functions'!$H$61)*(H11-'Elicitation of functions'!$H$61)+'Elicitation of functions'!$I$61))) -> 0.54166667 | S11: =IF(I11<'Elicitation of functions'!$H$70,('Elicitation of functions'!$I$70-'Elicitation of functions'!$I$72)/('Elicitation of functions'!$H$70-'Elicitation of functions'!$H$72)*(I11-'Elicitation of functions'!$H$72)+'Elicitation of functions'!$I$72,IF(I11<'Elicitation of functions'!$H$69,('Elicitation of functions'!$I$69-'Elicitation of functions'!$I$70)/('Elicitation of functions'!$H$69-'Elicitation of functions'!$H$70)*(I11-'Elicitation of functions'!$H$70)+'Elicitation of functions'!$I$70,IF(I11<'Elicitation of functions'!$H$71,('Elicitation of functions'!$I$71-'Elicitation of functions'!$I$69)/('Elicitation of functions'!$H$71-'Elicitation of functions'!$H$69)*(I11-'Elicitation of functions'!$H$69)+'Elicitation of functions'!$I$69,('Elicitation of functions'!$I$73-'Elicitation of functions'!$I$71)/('Elicitation of functions'!$H$73-'Elicitation of functions'!$H$71)*(I11-'Elicitation of functions'!$H$71)+'Elicitation of functions'!$I$71))) -> 0.5625 | T11: =INDEX('Elicitation of functions'!$K$79:$K$83,MATCH(J11,'Elicitation of functions'!$F$79:$F$83,0)) -> 0.35 | V11: 0.5 | W11: 0.75 | X11: 0.541667 | Y11: 0.5625 | Z11: 0.35
B12: Nordic-Baltic Tech Alliance | C12: 0.82 | D12: 0.75 | E12: Acceptable | F12: 1 | G12: Robust | H12: 0.65 | I12: 0.86 | J12: 4 | L12: =B12 -> Nordic-Baltic Tech Alliance | M12: =IF(C12<'Elicitation of functions'!$H$10,('Elicitation of functions'!$I$10-'Elicitation of functions'!$I$12)/('Elicitation of functions'!$H$10-'Elicitation of functions'!$H$12)*(C12-'Elicitation of functions'!$H$12)+'Elicitation of functions'!$I$12,IF(C12<'Elicitation of functions'!$H$9,('Elicitation of functions'!$I$9-'Elicitation of functions'!$I$10)/('Elicitation of functions'!$H$9-'Elicitation of functions'!$H$10)*(C12-'Elicitation of functions'!$H$10)+'Elicitation of functions'!$I$10,IF(C12<'Elicitation of functions'!$H$11,('Elicitation of functions'!$I$11-'Elicitation of functions'!$I$9)/('Elicitation of functions'!$H$11-'Elicitation of functions'!$H$9)*(C12-'Elicitation of functions'!$H$9)+'Elicitation of functions'!$I$9,('Elicitation of functions'!$I$13-'Elicitation of functions'!$I$11)/('Elicitation of functions'!$H$13-'Elicitation of functions'!$H$11)*(C12-'Elicitation of functions'!$H$11)+'Elicitation of functions'!$I$11))) -> 0.6 | N12: =IF(D12<'Elicitation of functions'!$H$20,('Elicitation of functions'!$I$20-'Elicitation of functions'!$I$22)/('Elicitation of functions'!$H$20-'Elicitation of functions'!$H$22)*(D12-'Elicitation of functions'!$H$22)+'Elicitation of functions'!$I$22,IF(D12<'Elicitation of functions'!$H$19,('Elicitation of functions'!$I$19-'Elicitation of functions'!$I$20)/('Elicitation of functions'!$H$19-'Elicitation of functions'!$H$20)*(D12-'Elicitation of functions'!$H$20)+'Elicitation of functions'!$I$20,IF(D12<'Elicitation of functions'!$H$21,('Elicitation of functions'!$I$21-'Elicitation of functions'!$I$19)/('Elicitation of functions'!$H$21-'Elicitation of functions'!$H$19)*(D12-'Elicitation of functions'!$H$19)+'Elicitation of functions'!$I$19,('Elicitation of functions'!$I$23-'Elicitation of functions'!$I$21)/('Elicitation of functions'!$H$23-'Elicitation of functions'!$H$21)*(D12-'Elicitation of functions'!$H$21)+'Elicitation of functions'!$I$21))) -> 0.59375 | O12: =INDEX('Elicitation of functions'!$K$29:$K$33,MATCH(E12,'Elicitation of functions'!$F$29:$F$33,0)) -> 0.4 | P12: =INDEX('Elicitation of functions'!$K$39:$K$43,MATCH(F12,'Elicitation of functions'!$F$39:$F$43,0)) -> 0.3 | Q12: =INDEX('Elicitation of functions'!$K$49:$K$52,MATCH(G12,'Elicitation of functions'!$F$49:$F$52,0)) -> 0.75 | R12: =IF(H12<'Elicitation of functions'!$H$60,('Elicitation of functions'!$I$60-'Elicitation of functions'!$I$62)/('Elicitation of functions'!$H$60-'Elicitation of functions'!$H$62)*(H12-'Elicitation of functions'!$H$62)+'Elicitation of functions'!$I$62,IF(H12<'Elicitation of functions'!$H$59,('Elicitation of functions'!$I$59-'Elicitation of functions'!$I$60)/('Elicitation of functions'!$H$59-'Elicitation of functions'!$H$60)*(H12-'Elicitation of functions'!$H$60)+'Elicitation of functions'!$I$60,IF(H12<'Elicitation of functions'!$H$61,('Elicitation of functions'!$I$61-'Elicitation of functions'!$I$59)/('Elicitation of functions'!$H$61-'Elicitation of functions'!$H$59)*(H12-'Elicitation of functions'!$H$59)+'Elicitation of functions'!$I$59,('Elicitation of functions'!$I$63-'Elicitation of functions'!$I$61)/('Elicitation of functions'!$H$63-'Elicitation of functions'!$H$61)*(H12-'Elicitation of functions'!$H$61)+'Elicitation of functions'!$I$61))) -> 0.66666667 | S12: =IF(I12<'Elicitation of functions'!$H$70,('Elicitation of functions'!$I$70-'Elicitation of functions'!$I$72)/('Elicitation of functions'!$H$70-'Elicitation of functions'!$H$72)*(I12-'Elicitation of functions'!$H$72)+'Elicitation of functions'!$I$72,IF(I12<'Elicitation of functions'!$H$69,('Elicitation of functions'!$I$69-'Elicitation of functions'!$I$70)/('Elicitation of functions'!$H$69-'Elicitation of functions'!$H$70)*(I12-'Elicitation of functions'!$H$70)+'Elicitation of functions'!$I$70,IF(I12<'Elicitation of functions'!$H$71,('Elicitation of functions'!$I$71-'Elicitation of functions'!$I$69)/('Elicitation of functions'!$H$71-'Elicitation of functions'!$H$69)*(I12-'Elicitation of functions'!$H$69)+'Elicitation of functions'!$I$69,('Elicitation of functions'!$I$73-'Elicitation of functions'!$I$71)/('Elicitation of functions'!$H$73-'Elicitation of functions'!$H$71)*(I12-'Elicitation of functions'!$H$71)+'Elicitation of functions'!$I$71))) -> 0.625 | T12: =INDEX('Elicitation of functions'!$K$79:$K$83,MATCH(J12,'Elicitation of functions'!$F$79:$F$83,0)) -> 0.7 | V12: 0.3 | W12: 0.75 | X12: 0.666667 | Y12: 0.625 | Z12: 0.7
B13: Scenario 2: Always-Learning Society | L13: Scenario 2: Always-Learning Society - Attribute-specific value scores
B14: Action | C14: Achievement of learning outcomes (65-95%) | D14: Completion and progression (55-90%) | E14: Learner experience and engagement | F14: Accessibility, flexibility and equity (0-4) | G14: Integrity of assessment | H14: Strategic control / autonomy (20-90%) | I14: External relevance and employability (65-95%) | J14: Global attractiveness / reputation (1-5) | L14: Action | M14: Achievement of learning outcomes (65-95%) | N14: Completion and progression (55-90%) | O14: Learner experience and engagement | P14: Accessibility, flexibility and equity (0-4) | Q14: Integrity of assessment | R14: Strategic control / autonomy (20-90%) | S14: External relevance and employability (65-95%) | T14: Global attractiveness / reputation (1-5)
B15: AI-Enabled Student Guidance | C15: 0.88 | D15: 0.85 | E15: Acceptable | F15: 4 | G15: Fragile | H15: 0.35 | I15: 0.85 | J15: 3 | L15: =B15 -> AI-Enabled Student Guidance | M15: =IF(C15<'Elicitation of functions'!$H$10,('Elicitation of functions'!$I$10-'Elicitation of functions'!$I$12)/('Elicitation of functions'!$H$10-'Elicitation of functions'!$H$12)*(C15-'Elicitation of functions'!$H$12)+'Elicitation of functions'!$I$12,IF(C15<'Elicitation of functions'!$H$9,('Elicitation of functions'!$I$9-'Elicitation of functions'!$I$10)/('Elicitation of functions'!$H$9-'Elicitation of functions'!$H$10)*(C15-'Elicitation of functions'!$H$10)+'Elicitation of functions'!$I$10,IF(C15<'Elicitation of functions'!$H$11,('Elicitation of functions'!$I$11-'Elicitation of functions'!$I$9)/('Elicitation of functions'!$H$11-'Elicitation of functions'!$H$9)*(C15-'Elicitation of functions'!$H$9)+'Elicitation of functions'!$I$9,('Elicitation of functions'!$I$13-'Elicitation of functions'!$I$11)/('Elicitation of functions'!$H$13-'Elicitation of functions'!$H$11)*(C15-'Elicitation of functions'!$H$11)+'Elicitation of functions'!$I$11))) -> 0.825 | N15: =IF(D15<'Elicitation of functions'!$H$20,('Elicitation of functions'!$I$20-'Elicitation of functions'!$I$22)/('Elicitation of functions'!$H$20-'Elicitation of functions'!$H$22)*(D15-'Elicitation of functions'!$H$22)+'Elicitation of functions'!$I$22,IF(D15<'Elicitation of functions'!$H$19,('Elicitation of functions'!$I$19-'Elicitation of functions'!$I$20)/('Elicitation of functions'!$H$19-'Elicitation of functions'!$H$20)*(D15-'Elicitation of functions'!$H$20)+'Elicitation of functions'!$I$20,IF(D15<'Elicitation of functions'!$H$21,('Elicitation of functions'!$I$21-'Elicitation of functions'!$I$19)/('Elicitation of functions'!$H$21-'Elicitation of functions'!$H$19)*(D15-'Elicitation of functions'!$H$19)+'Elicitation of functions'!$I$19,('Elicitation of functions'!$I$23-'Elicitation of functions'!$I$21)/('Elicitation of functions'!$H$23-'Elicitation of functions'!$H$21)*(D15-'Elicitation of functions'!$H$21)+'Elicitation of functions'!$I$21))) -> 0.875 | O15: =INDEX('Elicitation of functions'!$K$29:$K$33,MATCH(E15,'Elicitation of functions'!$F$29:$F$33,0)) -> 0.4 | P15: =INDEX('Elicitation of functions'!$K$39:$K$43,MATCH(F15,'Elicitation of functions'!$F$39:$F$43,0)) -> 1 | Q15: =INDEX('Elicitation of functions'!$K$49:$K$52,MATCH(G15,'Elicitation of functions'!$F$49:$F$52,0)) -> 0 | R15: =IF(H15<'Elicitation of functions'!$H$60,('Elicitation of functions'!$I$60-'Elicitation of functions'!$I$62)/('Elicitation of functions'!$H$60-'Elicitation of functions'!$H$62)*(H15-'Elicitation of functions'!$H$62)+'Elicitation of functions'!$I$62,IF(H15<'Elicitation of functions'!$H$59,('Elicitation of functions'!$I$59-'Elicitation of functions'!$I$60)/('Elicitation of functions'!$H$59-'Elicitation of functions'!$H$60)*(H15-'Elicitation of functions'!$H$60)+'Elicitation of functions'!$I$60,IF(H15<'Elicitation of functions'!$H$61,('Elicitation of functions'!$I$61-'Elicitation of functions'!$I$59)/('Elicitation of functions'!$H$61-'Elicitation of functions'!$H$59)*(H15-'Elicitation of functions'!$H$59)+'Elicitation of functions'!$I$59,('Elicitation of functions'!$I$63-'Elicitation of functions'!$I$61)/('Elicitation of functions'!$H$63-'Elicitation of functions'!$H$61)*(H15-'Elicitation of functions'!$H$61)+'Elicitation of functions'!$I$61))) -> 0.33333333 | S15: =IF(I15<'Elicitation of functions'!$H$70,('Elicitation of functions'!$I$70-'Elicitation of functions'!$I$72)/('Elicitation of functions'!$H$70-'Elicitation of functions'!$H$72)*(I15-'Elicitation of functions'!$H$72)+'Elicitation of functions'!$I$72,IF(I15<'Elicitation of functions'!$H$69,('Elicitation of functions'!$I$69-'Elicitation of functions'!$I$70)/('Elicitation of functions'!$H$69-'Elicitation of functions'!$H$70)*(I15-'Elicitation of functions'!$H$70)+'Elicitation of functions'!$I$70,IF(I15<'Elicitation of functions'!$H$71,('Elicitation of functions'!$I$71-'Elicitation of functions'!$I$69)/('Elicitation of functions'!$H$71-'Elicitation of functions'!$H$69)*(I15-'Elicitation of functions'!$H$69)+'Elicitation of functions'!$I$69,('Elicitation of functions'!$I$73-'Elicitation of functions'!$I$71)/('Elicitation of functions'!$H$73-'Elicitation of functions'!$H$71)*(I15-'Elicitation of functions'!$H$71)+'Elicitation of functions'!$I$71))) -> 0.59375 | T15: =INDEX('Elicitation of functions'!$K$79:$K$83,MATCH(J15,'Elicitation of functions'!$F$79:$F$83,0)) -> 0.35 | V15: 1 | W15: 0 | X15: 0.333333 | Y15: 0.59375 | Z15: 0.35
B16: Elite Mentor Network / Smart Work-Study | C16: 0.82 | D16: 0.8 | E16: Excellent | F16: 1 | G16: Robust | H16: 0.4 | I16: 0.95 | J16: 4 | L16: =B16 -> Elite Mentor Network / Smart Work-Study | M16: =IF(C16<'Elicitation of functions'!$H$10,('Elicitation of functions'!$I$10-'Elicitation of functions'!$I$12)/('Elicitation of functions'!$H$10-'Elicitation of functions'!$H$12)*(C16-'Elicitation of functions'!$H$12)+'Elicitation of functions'!$I$12,IF(C16<'Elicitation of functions'!$H$9,('Elicitation of functions'!$I$9-'Elicitation of functions'!$I$10)/('Elicitation of functions'!$H$9-'Elicitation of functions'!$H$10)*(C16-'Elicitation of functions'!$H$10)+'Elicitation of functions'!$I$10,IF(C16<'Elicitation of functions'!$H$11,('Elicitation of functions'!$I$11-'Elicitation of functions'!$I$9)/('Elicitation of functions'!$H$11-'Elicitation of functions'!$H$9)*(C16-'Elicitation of functions'!$H$9)+'Elicitation of functions'!$I$9,('Elicitation of functions'!$I$13-'Elicitation of functions'!$I$11)/('Elicitation of functions'!$H$13-'Elicitation of functions'!$H$11)*(C16-'Elicitation of functions'!$H$11)+'Elicitation of functions'!$I$11))) -> 0.6 | N16: =IF(D16<'Elicitation of functions'!$H$20,('Elicitation of functions'!$I$20-'Elicitation of functions'!$I$22)/('Elicitation of functions'!$H$20-'Elicitation of functions'!$H$22)*(D16-'Elicitation of functions'!$H$22)+'Elicitation of functions'!$I$22,IF(D16<'Elicitation of functions'!$H$19,('Elicitation of functions'!$I$19-'Elicitation of functions'!$I$20)/('Elicitation of functions'!$H$19-'Elicitation of functions'!$H$20)*(D16-'Elicitation of functions'!$H$20)+'Elicitation of functions'!$I$20,IF(D16<'Elicitation of functions'!$H$21,('Elicitation of functions'!$I$21-'Elicitation of functions'!$I$19)/('Elicitation of functions'!$H$21-'Elicitation of functions'!$H$19)*(D16-'Elicitation of functions'!$H$19)+'Elicitation of functions'!$I$19,('Elicitation of functions'!$I$23-'Elicitation of functions'!$I$21)/('Elicitation of functions'!$H$23-'Elicitation of functions'!$H$21)*(D16-'Elicitation of functions'!$H$21)+'Elicitation of functions'!$I$21))) -> 0.75 | O16: =INDEX('Elicitation of functions'!$K$29:$K$33,MATCH(E16,'Elicitation of functions'!$F$29:$F$33,0)) -> 1 | P16: =INDEX('Elicitation of functions'!$K$39:$K$43,MATCH(F16,'Elicitation of functions'!$F$39:$F$43,0)) -> 0.3 | Q16: =INDEX('Elicitation of functions'!$K$49:$K$52,MATCH(G16,'Elicitation of functions'!$F$49:$F$52,0)) -> 0.75 | R16: =IF(H16<'Elicitation of functions'!$H$60,('Elicitation of functions'!$I$60-'Elicitation of functions'!$I$62)/('Elicitation of functions'!$H$60-'Elicitation of functions'!$H$62)*(H16-'Elicitation of functions'!$H$62)+'Elicitation of functions'!$I$62,IF(H16<'Elicitation of functions'!$H$59,('Elicitation of functions'!$I$59-'Elicitation of functions'!$I$60)/('Elicitation of functions'!$H$59-'Elicitation of functions'!$H$60)*(H16-'Elicitation of functions'!$H$60)+'Elicitation of functions'!$I$60,IF(H16<'Elicitation of functions'!$H$61,('Elicitation of functions'!$I$61-'Elicitation of functions'!$I$59)/('Elicitation of functions'!$H$61-'Elicitation of functions'!$H$59)*(H16-'Elicitation of functions'!$H$59)+'Elicitation of functions'!$I$59,('Elicitation of functions'!$I$63-'Elicitation of functions'!$I$61)/('Elicitation of functions'!$H$63-'Elicitation of functions'!$H$61)*(H16-'Elicitation of functions'!$H$61)+'Elicitation of functions'!$I$61))) -> 0.41666667 | S16: =IF(I16<'Elicitation of functions'!$H$70,('Elicitation of functions'!$I$70-'Elicitation of functions'!$I$72)/('Elicitation of functions'!$H$70-'Elicitation of functions'!$H$72)*(I16-'Elicitation of functions'!$H$72)+'Elicitation of functions'!$I$72,IF(I16<'Elicitation of functions'!$H$69,('Elicitation of functions'!$I$69-'Elicitation of functions'!$I$70)/('Elicitation of functions'!$H$69-'Elicitation of functions'!$H$70)*(I16-'Elicitation of functions'!$H$70)+'Elicitation of functions'!$I$70,IF(I16<'Elicitation of functions'!$H$71,('Elicitation of functions'!$I$71-'Elicitation of functions'!$I$69)/('Elicitation of functions'!$H$71-'Elicitation of functions'!$H$69)*(I16-'Elicitation of functions'!$H$69)+'Elicitation of functions'!$I$69,('Elicitation of functions'!$I$73-'Elicitation of functions'!$I$71)/('Elicitation of functions'!$H$73-'Elicitation of functions'!$H$71)*(I16-'Elicitation of functions'!$H$71)+'Elicitation of functions'!$I$71))) -> 1 | T16: =INDEX('Elicitation of functions'!$K$79:$K$83,MATCH(J16,'Elicitation of functions'!$F$79:$F$83,0)) -> 0.7 | V16: 0.3 | W16: 0.75 | X16: 0.416667 | Y16: 1 | Z16: 0.7
B17: AI Governance Board / Assessment Integrity | C17: 0.78 | D17: 0.68 | E17: Poor | F17: 2 | G17: Exemplary | H17: 0.55 | I17: 0.82 | J17: 4 | L17: =B17 -> AI Governance Board / Assessment Integrity | M17: =IF(C17<'Elicitation of functions'!$H$10,('Elicitation of functions'!$I$10-'Elicitation of functions'!$I$12)/('Elicitation of functions'!$H$10-'Elicitation of functions'!$H$12)*(C17-'Elicitation of functions'!$H$12)+'Elicitation of functions'!$I$12,IF(C17<'Elicitation of functions'!$H$9,('Elicitation of functions'!$I$9-'Elicitation of functions'!$I$10)/('Elicitation of functions'!$H$9-'Elicitation of functions'!$H$10)*(C17-'Elicitation of functions'!$H$10)+'Elicitation of functions'!$I$10,IF(C17<'Elicitation of functions'!$H$11,('Elicitation of functions'!$I$11-'Elicitation of functions'!$I$9)/('Elicitation of functions'!$H$11-'Elicitation of functions'!$H$9)*(C17-'Elicitation of functions'!$H$9)+'Elicitation of functions'!$I$9,('Elicitation of functions'!$I$13-'Elicitation of functions'!$I$11)/('Elicitation of functions'!$H$13-'Elicitation of functions'!$H$11)*(C17-'Elicitation of functions'!$H$11)+'Elicitation of functions'!$I$11))) -> 0.4375 | N17: =IF(D17<'Elicitation of functions'!$H$20,('Elicitation of functions'!$I$20-'Elicitation of functions'!$I$22)/('Elicitation of functions'!$H$20-'Elicitation of functions'!$H$22)*(D17-'Elicitation of functions'!$H$22)+'Elicitation of functions'!$I$22,IF(D17<'Elicitation of functions'!$H$19,('Elicitation of functions'!$I$19-'Elicitation of functions'!$I$20)/('Elicitation of functions'!$H$19-'Elicitation of functions'!$H$20)*(D17-'Elicitation of functions'!$H$20)+'Elicitation of functions'!$I$20,IF(D17<'Elicitation of functions'!$H$21,('Elicitation of functions'!$I$21-'Elicitation of functions'!$I$19)/('Elicitation of functions'!$H$21-'Elicitation of functions'!$H$19)*(D17-'Elicitation of functions'!$H$19)+'Elicitation of functions'!$I$19,('Elicitation of functions'!$I$23-'Elicitation of functions'!$I$21)/('Elicitation of functions'!$H$23-'Elicitation of functions'!$H$21)*(D17-'Elicitation of functions'!$H$21)+'Elicitation of functions'!$I$21))) -> 0.35714286 | O17: =INDEX('Elicitation of functions'!$K$29:$K$33,MATCH(E17,'Elicitation of functions'!$F$29:$F$33,0)) -> 0.2 | P17: =INDEX('Elicitation of functions'!$K$39:$K$43,MATCH(F17,'Elicitation of functions'!$F$39:$F$43,0)) -> 0.5 | Q17: =INDEX('Elicitation of functions'!$K$49:$K$52,MATCH(G17,'Elicitation of functions'!$F$49:$F$52,0)) -> 1 | R17: =IF(H17<'Elicitation of functions'!$H$60,('Elicitation of functions'!$I$60-'Elicitation of functions'!$I$62)/('Elicitation of functions'!$H$60-'Elicitation of functions'!$H$62)*(H17-'Elicitation of functions'!$H$62)+'Elicitation of functions'!$I$62,IF(H17<'Elicitation of functions'!$H$59,('Elicitation of functions'!$I$59-'Elicitation of functions'!$I$60)/('Elicitation of functions'!$H$59-'Elicitation of functions'!$H$60)*(H17-'Elicitation of functions'!$H$60)+'Elicitation of functions'!$I$60,IF(H17<'Elicitation of functions'!$H$61,('Elicitation of functions'!$I$61-'Elicitation of functions'!$I$59)/('Elicitation of functions'!$H$61-'Elicitation of functions'!$H$59)*(H17-'Elicitation of functions'!$H$59)+'Elicitation of functions'!$I$59,('Elicitation of functions'!$I$63-'Elicitation of functions'!$I$61)/('Elicitation of functions'!$H$63-'Elicitation of functions'!$H$61)*(H17-'Elicitation of functions'!$H$61)+'Elicitation of functions'!$I$61))) -> 0.58333333 | S17: =IF(I17<'Elicitation of functions'!$H$70,('Elicitation of functions'!$I$70-'Elicitation of functions'!$I$72)/('Elicitation of functions'!$H$70-'Elicitation of functions'!$H$72)*(I17-'Elicitation of functions'!$H$72)+'Elicitation of functions'!$I$72,IF(I17<'Elicitation of functions'!$H$69,('Elicitation of functions'!$I$69-'Elicitation of functions'!$I$70)/('Elicitation of functions'!$H$69-'Elicitation of functions'!$H$70)*(I17-'Elicitation of functions'!$H$70)+'Elicitation of functions'!$I$70,IF(I17<'Elicitation of functions'!$H$71,('Elicitation of functions'!$I$71-'Elicitation of functions'!$I$69)/('Elicitation of functions'!$H$71-'Elicitation of functions'!$H$69)*(I17-'Elicitation of functions'!$H$69)+'Elicitation of functions'!$I$69,('Elicitation of functions'!$I$73-'Elicitation of functions'!$I$71)/('Elicitation of functions'!$H$73-'Elicitation of functions'!$H$71)*(I17-'Elicitation of functions'!$H$71)+'Elicitation of functions'!$I$71))) -> 0.5 | T17: =INDEX('Elicitation of functions'!$K$79:$K$83,MATCH(J17,'Elicitation of functions'!$F$79:$F$83,0)) -> 0.7 | V17: 0.5 | W17: 1 | X17: 0.583333 | Y17: 0.5 | Z17: 0.7
B18: Aalto-Controlled Core Infrastructure | C18: 0.82 | D18: 0.75 | E18: Poor | F18: 3 | G18: Robust | H18: 0.85 | I18: 0.85 | J18: 2 | L18: =B18 -> Aalto-Controlled Core Infrastructure | M18: =IF(C18<'Elicitation of functions'!$H$10,('Elicitation of functions'!$I$10-'Elicitation of functions'!$I$12)/('Elicitation of functions'!$H$10-'Elicitation of functions'!$H$12)*(C18-'Elicitation of functions'!$H$12)+'Elicitation of functions'!$I$12,IF(C18<'Elicitation of functions'!$H$9,('Elicitation of functions'!$I$9-'Elicitation of functions'!$I$10)/('Elicitation of functions'!$H$9-'Elicitation of functions'!$H$10)*(C18-'Elicitation of functions'!$H$10)+'Elicitation of functions'!$I$10,IF(C18<'Elicitation of functions'!$H$11,('Elicitation of functions'!$I$11-'Elicitation of functions'!$I$9)/('Elicitation of functions'!$H$11-'Elicitation of functions'!$H$9)*(C18-'Elicitation of functions'!$H$9)+'Elicitation of functions'!$I$9,('Elicitation of functions'!$I$13-'Elicitation of functions'!$I$11)/('Elicitation of functions'!$H$13-'Elicitation of functions'!$H$11)*(C18-'Elicitation of functions'!$H$11)+'Elicitation of functions'!$I$11))) -> 0.6 | N18: =IF(D18<'Elicitation of functions'!$H$20,('Elicitation of functions'!$I$20-'Elicitation of functions'!$I$22)/('Elicitation of functions'!$H$20-'Elicitation of functions'!$H$22)*(D18-'Elicitation of functions'!$H$22)+'Elicitation of functions'!$I$22,IF(D18<'Elicitation of functions'!$H$19,('Elicitation of functions'!$I$19-'Elicitation of functions'!$I$20)/('Elicitation of functions'!$H$19-'Elicitation of functions'!$H$20)*(D18-'Elicitation of functions'!$H$20)+'Elicitation of functions'!$I$20,IF(D18<'Elicitation of functions'!$H$21,('Elicitation of functions'!$I$21-'Elicitation of functions'!$I$19)/('Elicitation of functions'!$H$21-'Elicitation of functions'!$H$19)*(D18-'Elicitation of functions'!$H$19)+'Elicitation of functions'!$I$19,('Elicitation of functions'!$I$23-'Elicitation of functions'!$I$21)/('Elicitation of functions'!$H$23-'Elicitation of functions'!$H$21)*(D18-'Elicitation of functions'!$H$21)+'Elicitation of functions'!$I$21))) -> 0.59375 | O18: =INDEX('Elicitation of functions'!$K$29:$K$33,MATCH(E18,'Elicitation of functions'!$F$29:$F$33,0)) -> 0.2 | P18: =INDEX('Elicitation of functions'!$K$39:$K$43,MATCH(F18,'Elicitation of functions'!$F$39:$F$43,0)) -> 0.8 | Q18: =INDEX('Elicitation of functions'!$K$49:$K$52,MATCH(G18,'Elicitation of functions'!$F$49:$F$52,0)) -> 0.75 | R18: =IF(H18<'Elicitation of functions'!$H$60,('Elicitation of functions'!$I$60-'Elicitation of functions'!$I$62)/('Elicitation of functions'!$H$60-'Elicitation of functions'!$H$62)*(H18-'Elicitation of functions'!$H$62)+'Elicitation of functions'!$I$62,IF(H18<'Elicitation of functions'!$H$59,('Elicitation of functions'!$I$59-'Elicitation of functions'!$I$60)/('Elicitation of functions'!$H$59-'Elicitation of functions'!$H$60)*(H18-'Elicitation of functions'!$H$60)+'Elicitation of functions'!$I$60,IF(H18<'Elicitation of functions'!$H$61,('Elicitation of functions'!$I$61-'Elicitation of functions'!$I$59)/('Elicitation of functions'!$H$61-'Elicitation of functions'!$H$59)*(H18-'Elicitation of functions'!$H$59)+'Elicitation of functions'!$I$59,('Elicitation of functions'!$I$63-'Elicitation of functions'!$I$61)/('Elicitation of functions'!$H$63-'Elicitation of functions'!$H$61)*(H18-'Elicitation of functions'!$H$61)+'Elicitation of functions'!$I$61))) -> 0.91666667 | S18: =IF(I18<'Elicitation of functions'!$H$70,('Elicitation of functions'!$I$70-'Elicitation of functions'!$I$72)/('Elicitation of functions'!$H$70-'Elicitation of functions'!$H$72)*(I18-'Elicitation of functions'!$H$72)+'Elicitation of functions'!$I$72,IF(I18<'Elicitation of functions'!$H$69,('Elicitation of functions'!$I$69-'Elicitation of functions'!$I$70)/('Elicitation of functions'!$H$69-'Elicitation of functions'!$H$70)*(I18-'Elicitation of functions'!$H$70)+'Elicitation of functions'!$I$70,IF(I18<'Elicitation of functions'!$H$71,('Elicitation of functions'!$I$71-'Elicitation of functions'!$I$69)/('Elicitation of functions'!$H$71-'Elicitation of functions'!$H$69)*(I18-'Elicitation of functions'!$H$69)+'Elicitation of functions'!$I$69,('Elicitation of functions'!$I$73-'Elicitation of functions'!$I$71)/('Elicitation of functions'!$H$73-'Elicitation of functions'!$H$71)*(I18-'Elicitation of functions'!$H$71)+'Elicitation of functions'!$I$71))) -> 0.59375 | T18: =INDEX('Elicitation of functions'!$K$79:$K$83,MATCH(J18,'Elicitation of functions'!$F$79:$F$83,0)) -> 0.2 | V18: 0.8 | W18: 0.75 | X18: 0.916667 | Y18: 0.59375 | Z18: 0.2
